[2023-04-12T05:56:19.689+0000] {taskinstance.py:1090} INFO - Dependencies all met for dep_context=non-requeueable deps ti=<TaskInstance: first_dag.echo manual__2023-04-12T05:56:12.069517+00:00 [queued]>
[2023-04-12T05:56:19.698+0000] {taskinstance.py:1090} INFO - Dependencies all met for dep_context=requeueable deps ti=<TaskInstance: first_dag.echo manual__2023-04-12T05:56:12.069517+00:00 [queued]>
[2023-04-12T05:56:19.699+0000] {taskinstance.py:1288} INFO - 
--------------------------------------------------------------------------------
[2023-04-12T05:56:19.699+0000] {taskinstance.py:1289} INFO - Starting attempt 1 of 2
[2023-04-12T05:56:19.703+0000] {taskinstance.py:1290} INFO - 
--------------------------------------------------------------------------------
[2023-04-12T05:56:19.718+0000] {taskinstance.py:1309} INFO - Executing <Task(BashOperator): echo> on 2023-04-12 05:56:12.069517+00:00
[2023-04-12T05:56:19.722+0000] {standard_task_runner.py:55} INFO - Started process 624 to run task
[2023-04-12T05:56:19.725+0000] {standard_task_runner.py:82} INFO - Running: ['***', 'tasks', 'run', 'first_dag', 'echo', 'manual__2023-04-12T05:56:12.069517+00:00', '--job-id', '14', '--raw', '--subdir', 'DAGS_FOLDER/first_dag.py', '--cfg-path', '/tmp/tmpxrl6x2mh']
[2023-04-12T05:56:19.727+0000] {standard_task_runner.py:83} INFO - Job 14: Subtask echo
[2023-04-12T05:56:19.793+0000] {task_command.py:389} INFO - Running <TaskInstance: first_dag.echo manual__2023-04-12T05:56:12.069517+00:00 [running]> on host bb2ea0885db3
[2023-04-12T05:56:19.874+0000] {taskinstance.py:1518} INFO - Exporting the following env vars:
AIRFLOW_CTX_DAG_EMAIL=trungdq.httt@gmail.com
AIRFLOW_CTX_DAG_OWNER=***
AIRFLOW_CTX_DAG_ID=first_dag
AIRFLOW_CTX_TASK_ID=echo
AIRFLOW_CTX_EXECUTION_DATE=2023-04-12T05:56:12.069517+00:00
AIRFLOW_CTX_TRY_NUMBER=1
AIRFLOW_CTX_DAG_RUN_ID=manual__2023-04-12T05:56:12.069517+00:00
[2023-04-12T05:56:19.875+0000] {subprocess.py:63} INFO - Tmp dir root location: 
 /tmp
[2023-04-12T05:56:19.876+0000] {subprocess.py:75} INFO - Running command: ['/bin/bash', '-c', 'echo There is Airflow demo by Trungdq"']
[2023-04-12T05:56:19.882+0000] {subprocess.py:86} INFO - Output:
[2023-04-12T05:56:19.884+0000] {subprocess.py:93} INFO - /bin/bash: -c: line 1: unexpected EOF while looking for matching `"'
[2023-04-12T05:56:19.884+0000] {subprocess.py:93} INFO - /bin/bash: -c: line 2: syntax error: unexpected end of file
[2023-04-12T05:56:19.884+0000] {subprocess.py:97} INFO - Command exited with return code 2
[2023-04-12T05:56:19.894+0000] {taskinstance.py:1776} ERROR - Task failed with exception
Traceback (most recent call last):
  File "/home/airflow/.local/lib/python3.7/site-packages/airflow/operators/bash.py", line 197, in execute
    f"Bash command failed. The command returned a non-zero exit code {result.exit_code}."
airflow.exceptions.AirflowException: Bash command failed. The command returned a non-zero exit code 2.
[2023-04-12T05:56:19.897+0000] {taskinstance.py:1332} INFO - Marking task as UP_FOR_RETRY. dag_id=first_dag, task_id=echo, execution_date=20230412T055612, start_date=20230412T055619, end_date=20230412T055619
[2023-04-12T05:56:19.918+0000] {logging_mixin.py:137} WARNING - /home/***/.local/lib/python3.7/site-packages/***/utils/email.py:152 RemovedInAirflow3Warning: Fetching SMTP credentials from configuration variables will be deprecated in a future release. Please set credentials using a connection instead.
[2023-04-12T05:56:19.918+0000] {configuration.py:664} WARNING - section/key [smtp/smtp_user] not found in config
[2023-04-12T05:56:19.919+0000] {email.py:268} INFO - Email alerting: attempt 1
[2023-04-12T05:56:19.925+0000] {configuration.py:664} WARNING - section/key [smtp/smtp_user] not found in config
[2023-04-12T05:56:19.926+0000] {email.py:268} INFO - Email alerting: attempt 1
[2023-04-12T05:56:19.926+0000] {taskinstance.py:1839} ERROR - Failed to send email to: ['trungdq.httt@gmail.com']
Traceback (most recent call last):
  File "/home/airflow/.local/lib/python3.7/site-packages/airflow/models/taskinstance.py", line 1383, in _run_raw_task
    self._execute_task_with_callbacks(context, test_mode)
  File "/home/airflow/.local/lib/python3.7/site-packages/airflow/models/taskinstance.py", line 1529, in _execute_task_with_callbacks
    result = self._execute_task(context, task_orig)
  File "/home/airflow/.local/lib/python3.7/site-packages/airflow/models/taskinstance.py", line 1589, in _execute_task
    result = execute_callable(context=context)
  File "/home/airflow/.local/lib/python3.7/site-packages/airflow/operators/bash.py", line 197, in execute
    f"Bash command failed. The command returned a non-zero exit code {result.exit_code}."
airflow.exceptions.AirflowException: Bash command failed. The command returned a non-zero exit code 2.

During handling of the above exception, another exception occurred:

Traceback (most recent call last):
  File "/home/airflow/.local/lib/python3.7/site-packages/airflow/models/taskinstance.py", line 2239, in email_alert
    send_email(task.email, subject, html_content)
  File "/home/airflow/.local/lib/python3.7/site-packages/airflow/utils/email.py", line 91, in send_email
    **kwargs,
  File "/home/airflow/.local/lib/python3.7/site-packages/airflow/utils/email.py", line 152, in send_email_smtp
    send_mime_email(e_from=mail_from, e_to=recipients, mime_msg=msg, conn_id=conn_id, dryrun=dryrun)
  File "/home/airflow/.local/lib/python3.7/site-packages/airflow/utils/email.py", line 270, in send_mime_email
    smtp_conn = _get_smtp_connection(smtp_host, smtp_port, smtp_timeout, smtp_ssl)
  File "/home/airflow/.local/lib/python3.7/site-packages/airflow/utils/email.py", line 317, in _get_smtp_connection
    else smtplib.SMTP(host=host, port=port, timeout=timeout)
  File "/usr/local/lib/python3.7/smtplib.py", line 251, in __init__
    (code, msg) = self.connect(host, port)
  File "/usr/local/lib/python3.7/smtplib.py", line 336, in connect
    self.sock = self._get_socket(host, port, self.timeout)
  File "/usr/local/lib/python3.7/smtplib.py", line 307, in _get_socket
    self.source_address)
  File "/usr/local/lib/python3.7/socket.py", line 728, in create_connection
    raise err
  File "/usr/local/lib/python3.7/socket.py", line 716, in create_connection
    sock.connect(sa)
OSError: [Errno 99] Cannot assign requested address

During handling of the above exception, another exception occurred:

Traceback (most recent call last):
  File "/home/airflow/.local/lib/python3.7/site-packages/airflow/models/taskinstance.py", line 1837, in handle_failure
    self.email_alert(error, task)
  File "/home/airflow/.local/lib/python3.7/site-packages/airflow/models/taskinstance.py", line 2241, in email_alert
    send_email(task.email, subject, html_content_err)
  File "/home/airflow/.local/lib/python3.7/site-packages/airflow/utils/email.py", line 91, in send_email
    **kwargs,
  File "/home/airflow/.local/lib/python3.7/site-packages/airflow/utils/email.py", line 152, in send_email_smtp
    send_mime_email(e_from=mail_from, e_to=recipients, mime_msg=msg, conn_id=conn_id, dryrun=dryrun)
  File "/home/airflow/.local/lib/python3.7/site-packages/airflow/utils/email.py", line 270, in send_mime_email
    smtp_conn = _get_smtp_connection(smtp_host, smtp_port, smtp_timeout, smtp_ssl)
  File "/home/airflow/.local/lib/python3.7/site-packages/airflow/utils/email.py", line 317, in _get_smtp_connection
    else smtplib.SMTP(host=host, port=port, timeout=timeout)
  File "/usr/local/lib/python3.7/smtplib.py", line 251, in __init__
    (code, msg) = self.connect(host, port)
  File "/usr/local/lib/python3.7/smtplib.py", line 336, in connect
    self.sock = self._get_socket(host, port, self.timeout)
  File "/usr/local/lib/python3.7/smtplib.py", line 307, in _get_socket
    self.source_address)
  File "/usr/local/lib/python3.7/socket.py", line 728, in create_connection
    raise err
  File "/usr/local/lib/python3.7/socket.py", line 716, in create_connection
    sock.connect(sa)
OSError: [Errno 99] Cannot assign requested address
[2023-04-12T05:56:19.940+0000] {standard_task_runner.py:105} ERROR - Failed to execute job 14 for task echo (Bash command failed. The command returned a non-zero exit code 2.; 624)
[2023-04-12T05:56:19.978+0000] {local_task_job.py:212} INFO - Task exited with return code 1
[2023-04-12T05:56:19.993+0000] {taskinstance.py:2596} INFO - 0 downstream tasks scheduled from follow-on schedule check
