[2023-04-13T14:25:01.031+0000] {taskinstance.py:1090} INFO - Dependencies all met for dep_context=non-requeueable deps ti=<TaskInstance: first_dag.save_datetime scheduled__2023-04-13T14:24:00+00:00 [queued]>
[2023-04-13T14:25:01.194+0000] {taskinstance.py:1090} INFO - Dependencies all met for dep_context=requeueable deps ti=<TaskInstance: first_dag.save_datetime scheduled__2023-04-13T14:24:00+00:00 [queued]>
[2023-04-13T14:25:01.195+0000] {taskinstance.py:1288} INFO - 
--------------------------------------------------------------------------------
[2023-04-13T14:25:01.196+0000] {taskinstance.py:1289} INFO - Starting attempt 1 of 1
[2023-04-13T14:25:01.197+0000] {taskinstance.py:1290} INFO - 
--------------------------------------------------------------------------------
[2023-04-13T14:25:01.217+0000] {taskinstance.py:1309} INFO - Executing <Task(PythonOperator): save_datetime> on 2023-04-13 14:24:00+00:00
[2023-04-13T14:25:01.222+0000] {standard_task_runner.py:55} INFO - Started process 348 to run task
[2023-04-13T14:25:01.225+0000] {standard_task_runner.py:82} INFO - Running: ['***', 'tasks', 'run', 'first_dag', 'save_datetime', 'scheduled__2023-04-13T14:24:00+00:00', '--job-id', '32', '--raw', '--subdir', 'DAGS_FOLDER/first_dag.py', '--cfg-path', '/tmp/tmpva1t08n9']
[2023-04-13T14:25:01.228+0000] {standard_task_runner.py:83} INFO - Job 32: Subtask save_datetime
[2023-04-13T14:25:01.304+0000] {task_command.py:389} INFO - Running <TaskInstance: first_dag.save_datetime scheduled__2023-04-13T14:24:00+00:00 [running]> on host 6a1c33c9be4a
[2023-04-13T14:25:01.381+0000] {taskinstance.py:1518} INFO - Exporting the following env vars:
AIRFLOW_CTX_DAG_OWNER=***
AIRFLOW_CTX_DAG_ID=first_dag
AIRFLOW_CTX_TASK_ID=save_datetime
AIRFLOW_CTX_EXECUTION_DATE=2023-04-13T14:24:00+00:00
AIRFLOW_CTX_TRY_NUMBER=1
AIRFLOW_CTX_DAG_RUN_ID=scheduled__2023-04-13T14:24:00+00:00
[2023-04-13T14:25:01.392+0000] {taskinstance.py:1776} ERROR - Task failed with exception
Traceback (most recent call last):
  File "/home/airflow/.local/lib/python3.7/site-packages/airflow/operators/python.py", line 175, in execute
    return_value = self.execute_callable()
  File "/home/airflow/.local/lib/python3.7/site-packages/airflow/operators/python.py", line 192, in execute_callable
    return self.python_callable(*self.op_args, **self.op_kwargs)
  File "/opt/airflow/dags/first_dag.py", line 29, in save_datetime
    raise Exception('No processed datetime value.')
Exception: No processed datetime value.
[2023-04-13T14:25:01.401+0000] {taskinstance.py:1332} INFO - Marking task as FAILED. dag_id=first_dag, task_id=save_datetime, execution_date=20230413T142400, start_date=20230413T142501, end_date=20230413T142501
[2023-04-13T14:25:01.412+0000] {standard_task_runner.py:105} ERROR - Failed to execute job 32 for task save_datetime (No processed datetime value.; 348)
[2023-04-13T14:25:01.438+0000] {local_task_job.py:212} INFO - Task exited with return code 1
[2023-04-13T14:25:01.463+0000] {taskinstance.py:2596} INFO - 0 downstream tasks scheduled from follow-on schedule check
