[2023-04-13T14:21:00.596+0000] {taskinstance.py:1090} INFO - Dependencies all met for dep_context=non-requeueable deps ti=<TaskInstance: first_dag.process_datetime scheduled__2023-04-13T14:20:00+00:00 [queued]>
[2023-04-13T14:21:00.752+0000] {taskinstance.py:1090} INFO - Dependencies all met for dep_context=requeueable deps ti=<TaskInstance: first_dag.process_datetime scheduled__2023-04-13T14:20:00+00:00 [queued]>
[2023-04-13T14:21:00.752+0000] {taskinstance.py:1288} INFO - 
--------------------------------------------------------------------------------
[2023-04-13T14:21:00.753+0000] {taskinstance.py:1289} INFO - Starting attempt 1 of 1
[2023-04-13T14:21:00.754+0000] {taskinstance.py:1290} INFO - 
--------------------------------------------------------------------------------
[2023-04-13T14:21:00.773+0000] {taskinstance.py:1309} INFO - Executing <Task(PythonOperator): process_datetime> on 2023-04-13 14:20:00+00:00
[2023-04-13T14:21:00.777+0000] {standard_task_runner.py:55} INFO - Started process 198 to run task
[2023-04-13T14:21:00.782+0000] {standard_task_runner.py:82} INFO - Running: ['***', 'tasks', 'run', 'first_dag', 'process_datetime', 'scheduled__2023-04-13T14:20:00+00:00', '--job-id', '21', '--raw', '--subdir', 'DAGS_FOLDER/first_dag.py', '--cfg-path', '/tmp/tmpl6k27j8r']
[2023-04-13T14:21:00.786+0000] {standard_task_runner.py:83} INFO - Job 21: Subtask process_datetime
[2023-04-13T14:21:00.870+0000] {task_command.py:389} INFO - Running <TaskInstance: first_dag.process_datetime scheduled__2023-04-13T14:20:00+00:00 [running]> on host 6a1c33c9be4a
[2023-04-13T14:21:00.959+0000] {taskinstance.py:1518} INFO - Exporting the following env vars:
AIRFLOW_CTX_DAG_OWNER=***
AIRFLOW_CTX_DAG_ID=first_dag
AIRFLOW_CTX_TASK_ID=process_datetime
AIRFLOW_CTX_EXECUTION_DATE=2023-04-13T14:20:00+00:00
AIRFLOW_CTX_TRY_NUMBER=1
AIRFLOW_CTX_DAG_RUN_ID=scheduled__2023-04-13T14:20:00+00:00
[2023-04-13T14:21:00.979+0000] {taskinstance.py:1776} ERROR - Task failed with exception
Traceback (most recent call last):
  File "/home/airflow/.local/lib/python3.7/site-packages/airflow/operators/python.py", line 175, in execute
    return_value = self.execute_callable()
  File "/home/airflow/.local/lib/python3.7/site-packages/airflow/operators/python.py", line 192, in execute_callable
    return self.python_callable(*self.op_args, **self.op_kwargs)
  File "/opt/airflow/dags/first_dag.py", line 18, in process_datetime
    'year': dt[3],
IndexError: list index out of range
[2023-04-13T14:21:00.988+0000] {taskinstance.py:1332} INFO - Marking task as FAILED. dag_id=first_dag, task_id=process_datetime, execution_date=20230413T142000, start_date=20230413T142100, end_date=20230413T142100
[2023-04-13T14:21:01.004+0000] {standard_task_runner.py:105} ERROR - Failed to execute job 21 for task process_datetime (list index out of range; 198)
[2023-04-13T14:21:01.034+0000] {local_task_job.py:212} INFO - Task exited with return code 1
[2023-04-13T14:21:01.053+0000] {taskinstance.py:2596} INFO - 0 downstream tasks scheduled from follow-on schedule check
