[2023-04-13T14:35:13.172+0000] {taskinstance.py:1090} INFO - Dependencies all met for dep_context=non-requeueable deps ti=<TaskInstance: first_dag.process_datetime scheduled__2023-04-13T14:33:00+00:00 [queued]>
[2023-04-13T14:35:13.313+0000] {taskinstance.py:1090} INFO - Dependencies all met for dep_context=requeueable deps ti=<TaskInstance: first_dag.process_datetime scheduled__2023-04-13T14:33:00+00:00 [queued]>
[2023-04-13T14:35:13.314+0000] {taskinstance.py:1288} INFO - 
--------------------------------------------------------------------------------
[2023-04-13T14:35:13.314+0000] {taskinstance.py:1289} INFO - Starting attempt 1 of 1
[2023-04-13T14:35:13.315+0000] {taskinstance.py:1290} INFO - 
--------------------------------------------------------------------------------
[2023-04-13T14:35:13.332+0000] {taskinstance.py:1309} INFO - Executing <Task(PythonOperator): process_datetime> on 2023-04-13 14:33:00+00:00
[2023-04-13T14:35:13.337+0000] {standard_task_runner.py:55} INFO - Started process 691 to run task
[2023-04-13T14:35:13.340+0000] {standard_task_runner.py:82} INFO - Running: ['***', 'tasks', 'run', 'first_dag', 'process_datetime', 'scheduled__2023-04-13T14:33:00+00:00', '--job-id', '48', '--raw', '--subdir', 'DAGS_FOLDER/first_dag.py', '--cfg-path', '/tmp/tmpnig3emz9']
[2023-04-13T14:35:13.342+0000] {standard_task_runner.py:83} INFO - Job 48: Subtask process_datetime
[2023-04-13T14:35:13.411+0000] {task_command.py:389} INFO - Running <TaskInstance: first_dag.process_datetime scheduled__2023-04-13T14:33:00+00:00 [running]> on host 6a1c33c9be4a
[2023-04-13T14:35:13.485+0000] {taskinstance.py:1518} INFO - Exporting the following env vars:
AIRFLOW_CTX_DAG_OWNER=***
AIRFLOW_CTX_DAG_ID=first_dag
AIRFLOW_CTX_TASK_ID=process_datetime
AIRFLOW_CTX_EXECUTION_DATE=2023-04-13T14:33:00+00:00
AIRFLOW_CTX_TRY_NUMBER=1
AIRFLOW_CTX_DAG_RUN_ID=scheduled__2023-04-13T14:33:00+00:00
[2023-04-13T14:35:13.500+0000] {taskinstance.py:1776} ERROR - Task failed with exception
Traceback (most recent call last):
  File "/home/airflow/.local/lib/python3.7/site-packages/airflow/operators/python.py", line 175, in execute
    return_value = self.execute_callable()
  File "/home/airflow/.local/lib/python3.7/site-packages/airflow/operators/python.py", line 192, in execute_callable
    return self.python_callable(*self.op_args, **self.op_kwargs)
  File "/opt/airflow/dags/first_dag.py", line 19, in process_datetime
    'year': dt[3],
IndexError: list index out of range
[2023-04-13T14:35:13.508+0000] {taskinstance.py:1332} INFO - Marking task as FAILED. dag_id=first_dag, task_id=process_datetime, execution_date=20230413T143300, start_date=20230413T143513, end_date=20230413T143513
[2023-04-13T14:35:13.520+0000] {standard_task_runner.py:105} ERROR - Failed to execute job 48 for task process_datetime (list index out of range; 691)
[2023-04-13T14:35:13.552+0000] {local_task_job.py:212} INFO - Task exited with return code 1
[2023-04-13T14:35:13.578+0000] {taskinstance.py:2596} INFO - 0 downstream tasks scheduled from follow-on schedule check
