[2023-04-13T14:28:54.736+0000] {taskinstance.py:1090} INFO - Dependencies all met for dep_context=non-requeueable deps ti=<TaskInstance: first_dag.get_datetime manual__2023-04-13T14:28:53.625190+00:00 [queued]>
[2023-04-13T14:28:54.856+0000] {taskinstance.py:1090} INFO - Dependencies all met for dep_context=requeueable deps ti=<TaskInstance: first_dag.get_datetime manual__2023-04-13T14:28:53.625190+00:00 [queued]>
[2023-04-13T14:28:54.857+0000] {taskinstance.py:1288} INFO - 
--------------------------------------------------------------------------------
[2023-04-13T14:28:54.857+0000] {taskinstance.py:1289} INFO - Starting attempt 1 of 1
[2023-04-13T14:28:54.858+0000] {taskinstance.py:1290} INFO - 
--------------------------------------------------------------------------------
[2023-04-13T14:28:54.877+0000] {taskinstance.py:1309} INFO - Executing <Task(BashOperator): get_datetime> on 2023-04-13 14:28:53.625190+00:00
[2023-04-13T14:28:54.881+0000] {standard_task_runner.py:55} INFO - Started process 497 to run task
[2023-04-13T14:28:54.885+0000] {standard_task_runner.py:82} INFO - Running: ['***', 'tasks', 'run', 'first_dag', 'get_datetime', 'manual__2023-04-13T14:28:53.625190+00:00', '--job-id', '41', '--raw', '--subdir', 'DAGS_FOLDER/first_dag.py', '--cfg-path', '/tmp/tmpw7mzfs2d']
[2023-04-13T14:28:54.887+0000] {standard_task_runner.py:83} INFO - Job 41: Subtask get_datetime
[2023-04-13T14:28:54.955+0000] {task_command.py:389} INFO - Running <TaskInstance: first_dag.get_datetime manual__2023-04-13T14:28:53.625190+00:00 [running]> on host 6a1c33c9be4a
[2023-04-13T14:28:55.032+0000] {taskinstance.py:1518} INFO - Exporting the following env vars:
AIRFLOW_CTX_DAG_OWNER=***
AIRFLOW_CTX_DAG_ID=first_dag
AIRFLOW_CTX_TASK_ID=get_datetime
AIRFLOW_CTX_EXECUTION_DATE=2023-04-13T14:28:53.625190+00:00
AIRFLOW_CTX_TRY_NUMBER=1
AIRFLOW_CTX_DAG_RUN_ID=manual__2023-04-13T14:28:53.625190+00:00
[2023-04-13T14:28:55.033+0000] {subprocess.py:63} INFO - Tmp dir root location: 
 /tmp
[2023-04-13T14:28:55.034+0000] {subprocess.py:75} INFO - Running command: ['/bin/bash', '-c', 'Echo %date%-%time%']
[2023-04-13T14:28:55.042+0000] {subprocess.py:86} INFO - Output:
[2023-04-13T14:28:55.044+0000] {subprocess.py:93} INFO - /bin/bash: line 1: Echo: command not found
[2023-04-13T14:28:55.044+0000] {subprocess.py:97} INFO - Command exited with return code 127
[2023-04-13T14:28:55.055+0000] {taskinstance.py:1776} ERROR - Task failed with exception
Traceback (most recent call last):
  File "/home/airflow/.local/lib/python3.7/site-packages/airflow/operators/bash.py", line 197, in execute
    f"Bash command failed. The command returned a non-zero exit code {result.exit_code}."
airflow.exceptions.AirflowException: Bash command failed. The command returned a non-zero exit code 127.
[2023-04-13T14:28:55.059+0000] {taskinstance.py:1332} INFO - Marking task as FAILED. dag_id=first_dag, task_id=get_datetime, execution_date=20230413T142853, start_date=20230413T142854, end_date=20230413T142855
[2023-04-13T14:28:55.072+0000] {standard_task_runner.py:105} ERROR - Failed to execute job 41 for task get_datetime (Bash command failed. The command returned a non-zero exit code 127.; 497)
[2023-04-13T14:28:55.097+0000] {local_task_job.py:212} INFO - Task exited with return code 1
[2023-04-13T14:28:55.123+0000] {taskinstance.py:2596} INFO - 0 downstream tasks scheduled from follow-on schedule check
