[2023-04-13T14:35:13.190+0000] {taskinstance.py:1090} INFO - Dependencies all met for dep_context=non-requeueable deps ti=<TaskInstance: first_dag.process_datetime scheduled__2023-04-13T14:34:00+00:00 [queued]>
[2023-04-13T14:35:13.334+0000] {taskinstance.py:1090} INFO - Dependencies all met for dep_context=requeueable deps ti=<TaskInstance: first_dag.process_datetime scheduled__2023-04-13T14:34:00+00:00 [queued]>
[2023-04-13T14:35:13.334+0000] {taskinstance.py:1288} INFO - 
--------------------------------------------------------------------------------
[2023-04-13T14:35:13.335+0000] {taskinstance.py:1289} INFO - Starting attempt 1 of 1
[2023-04-13T14:35:13.335+0000] {taskinstance.py:1290} INFO - 
--------------------------------------------------------------------------------
[2023-04-13T14:35:13.352+0000] {taskinstance.py:1309} INFO - Executing <Task(PythonOperator): process_datetime> on 2023-04-13 14:34:00+00:00
[2023-04-13T14:35:13.357+0000] {standard_task_runner.py:55} INFO - Started process 692 to run task
[2023-04-13T14:35:13.360+0000] {standard_task_runner.py:82} INFO - Running: ['***', 'tasks', 'run', 'first_dag', 'process_datetime', 'scheduled__2023-04-13T14:34:00+00:00', '--job-id', '50', '--raw', '--subdir', 'DAGS_FOLDER/first_dag.py', '--cfg-path', '/tmp/tmp1aa71utx']
[2023-04-13T14:35:13.363+0000] {standard_task_runner.py:83} INFO - Job 50: Subtask process_datetime
[2023-04-13T14:35:13.430+0000] {task_command.py:389} INFO - Running <TaskInstance: first_dag.process_datetime scheduled__2023-04-13T14:34:00+00:00 [running]> on host 6a1c33c9be4a
[2023-04-13T14:35:13.514+0000] {taskinstance.py:1518} INFO - Exporting the following env vars:
AIRFLOW_CTX_DAG_OWNER=***
AIRFLOW_CTX_DAG_ID=first_dag
AIRFLOW_CTX_TASK_ID=process_datetime
AIRFLOW_CTX_EXECUTION_DATE=2023-04-13T14:34:00+00:00
AIRFLOW_CTX_TRY_NUMBER=1
AIRFLOW_CTX_DAG_RUN_ID=scheduled__2023-04-13T14:34:00+00:00
[2023-04-13T14:35:13.530+0000] {taskinstance.py:1776} ERROR - Task failed with exception
Traceback (most recent call last):
  File "/home/airflow/.local/lib/python3.7/site-packages/airflow/operators/python.py", line 175, in execute
    return_value = self.execute_callable()
  File "/home/airflow/.local/lib/python3.7/site-packages/airflow/operators/python.py", line 192, in execute_callable
    return self.python_callable(*self.op_args, **self.op_kwargs)
  File "/opt/airflow/dags/first_dag.py", line 19, in process_datetime
    'year': dt[3],
IndexError: list index out of range
[2023-04-13T14:35:13.538+0000] {taskinstance.py:1332} INFO - Marking task as FAILED. dag_id=first_dag, task_id=process_datetime, execution_date=20230413T143400, start_date=20230413T143513, end_date=20230413T143513
[2023-04-13T14:35:13.553+0000] {standard_task_runner.py:105} ERROR - Failed to execute job 50 for task process_datetime (list index out of range; 692)
[2023-04-13T14:35:13.573+0000] {local_task_job.py:212} INFO - Task exited with return code 1
[2023-04-13T14:35:13.600+0000] {taskinstance.py:2596} INFO - 0 downstream tasks scheduled from follow-on schedule check
